<?xml version="1.0" encoding="utf-8"?>
<!-- This URDF was automatically created by SolidWorks to URDF Exporter! Originally created by Stephen Brawner (brawner@gmail.com) 
     Commit Version: 1.5.1-0-g916b5db  Build Version: 1.5.7152.31018
     For more information, please see http://wiki.ros.org/sw_urdf_exporter -->
<robot
  name="Gripper URDF">
  <link
    name="base_gripper">
    <inertial>
      <origin
        xyz="-0.0204211188208551 1.28751831478431E-18 3.63413667128383E-19"
        rpy="0 0 0" />
      <mass
        value="0.786634201066895" />
      <inertia
        ixx="0.000460892604648364"
        ixy="1.91480919093637E-20"
        ixz="-8.67827343842154E-21"
        iyy="0.000924570118396014"
        iyz="-8.94756696521781E-21"
        izz="0.00118611546150363" />
    </inertial>
    <visual>
      <origin
        xyz="0 0 0"
        rpy="0 0 0" />
      <geometry>
        <mesh
          filename="package://Gripper URDF/meshes/base_gripper.STL" />
      </geometry>
      <material
        name="">
        <color
          rgba="0.898039215686275 0.917647058823529 0.929411764705882 1" />
      </material>
    </visual>
    <collision>
      <origin
        xyz="0 0 0"
        rpy="0 0 0" />
      <geometry>
        <mesh
          filename="package://Gripper URDF/meshes/base_gripper.STL" />
      </geometry>
    </collision>
  </link>
  <link
    name="top_finger">
    <inertial>
      <origin
        xyz="0.0569761702842869 0.0153366049733551 -2.28164314810049E-09"
        rpy="0 0 0" />
      <mass
        value="0.016699807063818" />
      <inertia
        ixx="1.70014563215441E-06"
        ixy="-2.62000269281901E-07"
        ixz="1.45877071218293E-12"
        iyy="2.82131218304835E-05"
        iyz="-2.19172940313993E-13"
        izz="2.84501465606867E-05" />
    </inertial>
    <visual>
      <origin
        xyz="0 0 0"
        rpy="0 0 0" />
      <geometry>
        <mesh
          filename="package://Gripper URDF/meshes/top_finger.STL" />
      </geometry>
      <material
        name="">
        <color
          rgba="1 1 1 1" />
      </material>
    </visual>
    <collision>
      <origin
        xyz="0 0 0"
        rpy="0 0 0" />
      <geometry>
        <mesh
          filename="package://Gripper URDF/meshes/top_finger.STL" />
      </geometry>
    </collision>
  </link>
  <joint
    name="joint_top"
    type="continuous">
    <origin
      xyz="0.055 0 0"
      rpy="1.5708 -0.13844 0" />
    <parent
      link="base_gripper" />
    <child
      link="top_finger" />
    <axis
      xyz="0 0 1" />
  </joint>
  <link
    name="bottom_finger">
    <inertial>
      <origin
        xyz="0.052556064130849 0.013895592166469 2.33049959033256E-07"
        rpy="0 0 0" />
      <mass
        value="0.0166412268723713" />
      <inertia
        ixx="1.43312220084271E-06"
        ixy="-1.15712620736261E-06"
        ixz="-2.27936154732058E-10"
        iyy="3.25661558107561E-05"
        iyz="-1.99946204981851E-11"
        izz="3.33752733872423E-05" />
    </inertial>
    <visual>
      <origin
        xyz="0 0 0"
        rpy="0 0 0" />
      <geometry>
        <mesh
          filename="package://Gripper URDF/meshes/bottom_finger.STL" />
      </geometry>
      <material
        name="">
        <color
          rgba="1 1 1 1" />
      </material>
    </visual>
    <collision>
      <origin
        xyz="0 0 0"
        rpy="0 0 0" />
      <geometry>
        <mesh
          filename="package://Gripper URDF/meshes/bottom_finger.STL" />
      </geometry>
    </collision>
  </link>
  <joint
    name="joint_bottom"
    type="continuous">
    <origin
      xyz="0.055 0 0"
      rpy="-1.5707963267949 0.112613956633998 0" />
    <parent
      link="base_gripper" />
    <child
      link="bottom_finger" />
    <axis
      xyz="0 0 1" />
  </joint>
</robot>